{
 "cells": [
  {
   "cell_type": "code",
   "execution_count": 7,
   "metadata": {},
   "outputs": [],
   "source": [
    "import boto3"
   ]
  },
  {
   "cell_type": "code",
   "execution_count": 8,
   "metadata": {},
   "outputs": [],
   "source": [
    "bucket_name = 'gcw-rimbunio-common-input-data-dev'"
   ]
  },
  {
   "cell_type": "code",
   "execution_count": 9,
   "metadata": {},
   "outputs": [],
   "source": [
    "s3client = boto3.client('s3')"
   ]
  },
  {
   "cell_type": "code",
   "execution_count": 10,
   "metadata": {},
   "outputs": [
    {
     "ename": "ClientError",
     "evalue": "An error occurred (InvalidAccessKeyId) when calling the ListObjects operation: The AWS Access Key Id you provided does not exist in our records.",
     "output_type": "error",
     "traceback": [
      "\u001b[0;31m---------------------------------------------------------------------------\u001b[0m",
      "\u001b[0;31mClientError\u001b[0m                               Traceback (most recent call last)",
      "\u001b[0;32m<ipython-input-10-2354dc7c0c81>\u001b[0m in \u001b[0;36m<module>\u001b[0;34m()\u001b[0m\n\u001b[0;32m----> 1\u001b[0;31m \u001b[0ms3client\u001b[0m\u001b[0;34m.\u001b[0m\u001b[0mlist_objects\u001b[0m\u001b[0;34m(\u001b[0m\u001b[0mBucket\u001b[0m \u001b[0;34m=\u001b[0m \u001b[0mbucket_name\u001b[0m\u001b[0;34m)\u001b[0m\u001b[0;34m[\u001b[0m\u001b[0;34m'Contents'\u001b[0m\u001b[0;34m]\u001b[0m\u001b[0;34m\u001b[0m\u001b[0m\n\u001b[0m",
      "\u001b[0;32m~/anaconda3/envs/python3/lib/python3.6/site-packages/botocore/client.py\u001b[0m in \u001b[0;36m_api_call\u001b[0;34m(self, *args, **kwargs)\u001b[0m\n\u001b[1;32m    314\u001b[0m                     \"%s() only accepts keyword arguments.\" % py_operation_name)\n\u001b[1;32m    315\u001b[0m             \u001b[0;31m# The \"self\" in this scope is referring to the BaseClient.\u001b[0m\u001b[0;34m\u001b[0m\u001b[0;34m\u001b[0m\u001b[0m\n\u001b[0;32m--> 316\u001b[0;31m             \u001b[0;32mreturn\u001b[0m \u001b[0mself\u001b[0m\u001b[0;34m.\u001b[0m\u001b[0m_make_api_call\u001b[0m\u001b[0;34m(\u001b[0m\u001b[0moperation_name\u001b[0m\u001b[0;34m,\u001b[0m \u001b[0mkwargs\u001b[0m\u001b[0;34m)\u001b[0m\u001b[0;34m\u001b[0m\u001b[0m\n\u001b[0m\u001b[1;32m    317\u001b[0m \u001b[0;34m\u001b[0m\u001b[0m\n\u001b[1;32m    318\u001b[0m         \u001b[0m_api_call\u001b[0m\u001b[0;34m.\u001b[0m\u001b[0m__name__\u001b[0m \u001b[0;34m=\u001b[0m \u001b[0mstr\u001b[0m\u001b[0;34m(\u001b[0m\u001b[0mpy_operation_name\u001b[0m\u001b[0;34m)\u001b[0m\u001b[0;34m\u001b[0m\u001b[0m\n",
      "\u001b[0;32m~/anaconda3/envs/python3/lib/python3.6/site-packages/botocore/client.py\u001b[0m in \u001b[0;36m_make_api_call\u001b[0;34m(self, operation_name, api_params)\u001b[0m\n\u001b[1;32m    624\u001b[0m             \u001b[0merror_code\u001b[0m \u001b[0;34m=\u001b[0m \u001b[0mparsed_response\u001b[0m\u001b[0;34m.\u001b[0m\u001b[0mget\u001b[0m\u001b[0;34m(\u001b[0m\u001b[0;34m\"Error\"\u001b[0m\u001b[0;34m,\u001b[0m \u001b[0;34m{\u001b[0m\u001b[0;34m}\u001b[0m\u001b[0;34m)\u001b[0m\u001b[0;34m.\u001b[0m\u001b[0mget\u001b[0m\u001b[0;34m(\u001b[0m\u001b[0;34m\"Code\"\u001b[0m\u001b[0;34m)\u001b[0m\u001b[0;34m\u001b[0m\u001b[0m\n\u001b[1;32m    625\u001b[0m             \u001b[0merror_class\u001b[0m \u001b[0;34m=\u001b[0m \u001b[0mself\u001b[0m\u001b[0;34m.\u001b[0m\u001b[0mexceptions\u001b[0m\u001b[0;34m.\u001b[0m\u001b[0mfrom_code\u001b[0m\u001b[0;34m(\u001b[0m\u001b[0merror_code\u001b[0m\u001b[0;34m)\u001b[0m\u001b[0;34m\u001b[0m\u001b[0m\n\u001b[0;32m--> 626\u001b[0;31m             \u001b[0;32mraise\u001b[0m \u001b[0merror_class\u001b[0m\u001b[0;34m(\u001b[0m\u001b[0mparsed_response\u001b[0m\u001b[0;34m,\u001b[0m \u001b[0moperation_name\u001b[0m\u001b[0;34m)\u001b[0m\u001b[0;34m\u001b[0m\u001b[0m\n\u001b[0m\u001b[1;32m    627\u001b[0m         \u001b[0;32melse\u001b[0m\u001b[0;34m:\u001b[0m\u001b[0;34m\u001b[0m\u001b[0m\n\u001b[1;32m    628\u001b[0m             \u001b[0;32mreturn\u001b[0m \u001b[0mparsed_response\u001b[0m\u001b[0;34m\u001b[0m\u001b[0m\n",
      "\u001b[0;31mClientError\u001b[0m: An error occurred (InvalidAccessKeyId) when calling the ListObjects operation: The AWS Access Key Id you provided does not exist in our records."
     ]
    }
   ],
   "source": [
    "s3client.list_objects(Bucket = bucket_name)['Contents']"
   ]
  },
  {
   "cell_type": "code",
   "execution_count": 5,
   "metadata": {},
   "outputs": [
    {
     "ename": "ClientError",
     "evalue": "An error occurred (InvalidAccessKeyId) when calling the ListObjects operation: The AWS Access Key Id you provided does not exist in our records.",
     "output_type": "error",
     "traceback": [
      "\u001b[0;31m---------------------------------------------------------------------------\u001b[0m",
      "\u001b[0;31mClientError\u001b[0m                               Traceback (most recent call last)",
      "\u001b[0;32m<ipython-input-5-0bc3278417a6>\u001b[0m in \u001b[0;36m<module>\u001b[0;34m()\u001b[0m\n\u001b[0;32m----> 1\u001b[0;31m \u001b[0ms3client\u001b[0m\u001b[0;34m.\u001b[0m\u001b[0mlist_objects\u001b[0m\u001b[0;34m(\u001b[0m\u001b[0mBucket\u001b[0m\u001b[0;34m=\u001b[0m\u001b[0;34m'gcw-rimbunio-common-input-data-dev'\u001b[0m\u001b[0;34m)\u001b[0m\u001b[0;34m\u001b[0m\u001b[0m\n\u001b[0m",
      "\u001b[0;32m~/anaconda3/envs/python3/lib/python3.6/site-packages/botocore/client.py\u001b[0m in \u001b[0;36m_api_call\u001b[0;34m(self, *args, **kwargs)\u001b[0m\n\u001b[1;32m    314\u001b[0m                     \"%s() only accepts keyword arguments.\" % py_operation_name)\n\u001b[1;32m    315\u001b[0m             \u001b[0;31m# The \"self\" in this scope is referring to the BaseClient.\u001b[0m\u001b[0;34m\u001b[0m\u001b[0;34m\u001b[0m\u001b[0m\n\u001b[0;32m--> 316\u001b[0;31m             \u001b[0;32mreturn\u001b[0m \u001b[0mself\u001b[0m\u001b[0;34m.\u001b[0m\u001b[0m_make_api_call\u001b[0m\u001b[0;34m(\u001b[0m\u001b[0moperation_name\u001b[0m\u001b[0;34m,\u001b[0m \u001b[0mkwargs\u001b[0m\u001b[0;34m)\u001b[0m\u001b[0;34m\u001b[0m\u001b[0m\n\u001b[0m\u001b[1;32m    317\u001b[0m \u001b[0;34m\u001b[0m\u001b[0m\n\u001b[1;32m    318\u001b[0m         \u001b[0m_api_call\u001b[0m\u001b[0;34m.\u001b[0m\u001b[0m__name__\u001b[0m \u001b[0;34m=\u001b[0m \u001b[0mstr\u001b[0m\u001b[0;34m(\u001b[0m\u001b[0mpy_operation_name\u001b[0m\u001b[0;34m)\u001b[0m\u001b[0;34m\u001b[0m\u001b[0m\n",
      "\u001b[0;32m~/anaconda3/envs/python3/lib/python3.6/site-packages/botocore/client.py\u001b[0m in \u001b[0;36m_make_api_call\u001b[0;34m(self, operation_name, api_params)\u001b[0m\n\u001b[1;32m    624\u001b[0m             \u001b[0merror_code\u001b[0m \u001b[0;34m=\u001b[0m \u001b[0mparsed_response\u001b[0m\u001b[0;34m.\u001b[0m\u001b[0mget\u001b[0m\u001b[0;34m(\u001b[0m\u001b[0;34m\"Error\"\u001b[0m\u001b[0;34m,\u001b[0m \u001b[0;34m{\u001b[0m\u001b[0;34m}\u001b[0m\u001b[0;34m)\u001b[0m\u001b[0;34m.\u001b[0m\u001b[0mget\u001b[0m\u001b[0;34m(\u001b[0m\u001b[0;34m\"Code\"\u001b[0m\u001b[0;34m)\u001b[0m\u001b[0;34m\u001b[0m\u001b[0m\n\u001b[1;32m    625\u001b[0m             \u001b[0merror_class\u001b[0m \u001b[0;34m=\u001b[0m \u001b[0mself\u001b[0m\u001b[0;34m.\u001b[0m\u001b[0mexceptions\u001b[0m\u001b[0;34m.\u001b[0m\u001b[0mfrom_code\u001b[0m\u001b[0;34m(\u001b[0m\u001b[0merror_code\u001b[0m\u001b[0;34m)\u001b[0m\u001b[0;34m\u001b[0m\u001b[0m\n\u001b[0;32m--> 626\u001b[0;31m             \u001b[0;32mraise\u001b[0m \u001b[0merror_class\u001b[0m\u001b[0;34m(\u001b[0m\u001b[0mparsed_response\u001b[0m\u001b[0;34m,\u001b[0m \u001b[0moperation_name\u001b[0m\u001b[0;34m)\u001b[0m\u001b[0;34m\u001b[0m\u001b[0m\n\u001b[0m\u001b[1;32m    627\u001b[0m         \u001b[0;32melse\u001b[0m\u001b[0;34m:\u001b[0m\u001b[0;34m\u001b[0m\u001b[0m\n\u001b[1;32m    628\u001b[0m             \u001b[0;32mreturn\u001b[0m \u001b[0mparsed_response\u001b[0m\u001b[0;34m\u001b[0m\u001b[0m\n",
      "\u001b[0;31mClientError\u001b[0m: An error occurred (InvalidAccessKeyId) when calling the ListObjects operation: The AWS Access Key Id you provided does not exist in our records."
     ]
    }
   ],
   "source": [
    "s3client.list_objects(Bucket='gcw-rimbunio-common-input-data-dev')"
   ]
  },
  {
   "cell_type": "code",
   "execution_count": 6,
   "metadata": {},
   "outputs": [
    {
     "ename": "ClientError",
     "evalue": "An error occurred (InvalidAccessKeyId) when calling the ListObjects operation: The AWS Access Key Id you provided does not exist in our records.",
     "output_type": "error",
     "traceback": [
      "\u001b[0;31m---------------------------------------------------------------------------\u001b[0m",
      "\u001b[0;31mClientError\u001b[0m                               Traceback (most recent call last)",
      "\u001b[0;32m<ipython-input-6-9be3c1adb3a7>\u001b[0m in \u001b[0;36m<module>\u001b[0;34m()\u001b[0m\n\u001b[0;32m----> 1\u001b[0;31m \u001b[0;32mfor\u001b[0m \u001b[0mobj\u001b[0m \u001b[0;32min\u001b[0m \u001b[0ms3client\u001b[0m\u001b[0;34m.\u001b[0m\u001b[0mlist_objects\u001b[0m\u001b[0;34m(\u001b[0m\u001b[0mBucket\u001b[0m\u001b[0;34m=\u001b[0m\u001b[0;34m'mybucket'\u001b[0m\u001b[0;34m)\u001b[0m\u001b[0;34m[\u001b[0m\u001b[0;34m'Contents'\u001b[0m\u001b[0;34m]\u001b[0m\u001b[0;34m:\u001b[0m\u001b[0;34m\u001b[0m\u001b[0m\n\u001b[0m\u001b[1;32m      2\u001b[0m     \u001b[0;32mtry\u001b[0m\u001b[0;34m:\u001b[0m\u001b[0;34m\u001b[0m\u001b[0m\n\u001b[1;32m      3\u001b[0m         \u001b[0mfilename\u001b[0m \u001b[0;34m=\u001b[0m \u001b[0mobj\u001b[0m\u001b[0;34m[\u001b[0m\u001b[0;34m'Key'\u001b[0m\u001b[0;34m]\u001b[0m\u001b[0;34m.\u001b[0m\u001b[0mrsplit\u001b[0m\u001b[0;34m(\u001b[0m\u001b[0;34m'/'\u001b[0m\u001b[0;34m,\u001b[0m \u001b[0;36m1\u001b[0m\u001b[0;34m)\u001b[0m\u001b[0;34m[\u001b[0m\u001b[0;36m1\u001b[0m\u001b[0;34m]\u001b[0m\u001b[0;34m\u001b[0m\u001b[0m\n\u001b[1;32m      4\u001b[0m     \u001b[0;32mexcept\u001b[0m \u001b[0mIndexError\u001b[0m\u001b[0;34m:\u001b[0m\u001b[0;34m\u001b[0m\u001b[0m\n\u001b[1;32m      5\u001b[0m         \u001b[0mfilename\u001b[0m \u001b[0;34m=\u001b[0m \u001b[0mobj\u001b[0m\u001b[0;34m[\u001b[0m\u001b[0;34m'Key'\u001b[0m\u001b[0;34m]\u001b[0m\u001b[0;34m\u001b[0m\u001b[0m\n",
      "\u001b[0;32m~/anaconda3/envs/python3/lib/python3.6/site-packages/botocore/client.py\u001b[0m in \u001b[0;36m_api_call\u001b[0;34m(self, *args, **kwargs)\u001b[0m\n\u001b[1;32m    314\u001b[0m                     \"%s() only accepts keyword arguments.\" % py_operation_name)\n\u001b[1;32m    315\u001b[0m             \u001b[0;31m# The \"self\" in this scope is referring to the BaseClient.\u001b[0m\u001b[0;34m\u001b[0m\u001b[0;34m\u001b[0m\u001b[0m\n\u001b[0;32m--> 316\u001b[0;31m             \u001b[0;32mreturn\u001b[0m \u001b[0mself\u001b[0m\u001b[0;34m.\u001b[0m\u001b[0m_make_api_call\u001b[0m\u001b[0;34m(\u001b[0m\u001b[0moperation_name\u001b[0m\u001b[0;34m,\u001b[0m \u001b[0mkwargs\u001b[0m\u001b[0;34m)\u001b[0m\u001b[0;34m\u001b[0m\u001b[0m\n\u001b[0m\u001b[1;32m    317\u001b[0m \u001b[0;34m\u001b[0m\u001b[0m\n\u001b[1;32m    318\u001b[0m         \u001b[0m_api_call\u001b[0m\u001b[0;34m.\u001b[0m\u001b[0m__name__\u001b[0m \u001b[0;34m=\u001b[0m \u001b[0mstr\u001b[0m\u001b[0;34m(\u001b[0m\u001b[0mpy_operation_name\u001b[0m\u001b[0;34m)\u001b[0m\u001b[0;34m\u001b[0m\u001b[0m\n",
      "\u001b[0;32m~/anaconda3/envs/python3/lib/python3.6/site-packages/botocore/client.py\u001b[0m in \u001b[0;36m_make_api_call\u001b[0;34m(self, operation_name, api_params)\u001b[0m\n\u001b[1;32m    624\u001b[0m             \u001b[0merror_code\u001b[0m \u001b[0;34m=\u001b[0m \u001b[0mparsed_response\u001b[0m\u001b[0;34m.\u001b[0m\u001b[0mget\u001b[0m\u001b[0;34m(\u001b[0m\u001b[0;34m\"Error\"\u001b[0m\u001b[0;34m,\u001b[0m \u001b[0;34m{\u001b[0m\u001b[0;34m}\u001b[0m\u001b[0;34m)\u001b[0m\u001b[0;34m.\u001b[0m\u001b[0mget\u001b[0m\u001b[0;34m(\u001b[0m\u001b[0;34m\"Code\"\u001b[0m\u001b[0;34m)\u001b[0m\u001b[0;34m\u001b[0m\u001b[0m\n\u001b[1;32m    625\u001b[0m             \u001b[0merror_class\u001b[0m \u001b[0;34m=\u001b[0m \u001b[0mself\u001b[0m\u001b[0;34m.\u001b[0m\u001b[0mexceptions\u001b[0m\u001b[0;34m.\u001b[0m\u001b[0mfrom_code\u001b[0m\u001b[0;34m(\u001b[0m\u001b[0merror_code\u001b[0m\u001b[0;34m)\u001b[0m\u001b[0;34m\u001b[0m\u001b[0m\n\u001b[0;32m--> 626\u001b[0;31m             \u001b[0;32mraise\u001b[0m \u001b[0merror_class\u001b[0m\u001b[0;34m(\u001b[0m\u001b[0mparsed_response\u001b[0m\u001b[0;34m,\u001b[0m \u001b[0moperation_name\u001b[0m\u001b[0;34m)\u001b[0m\u001b[0;34m\u001b[0m\u001b[0m\n\u001b[0m\u001b[1;32m    627\u001b[0m         \u001b[0;32melse\u001b[0m\u001b[0;34m:\u001b[0m\u001b[0;34m\u001b[0m\u001b[0m\n\u001b[1;32m    628\u001b[0m             \u001b[0;32mreturn\u001b[0m \u001b[0mparsed_response\u001b[0m\u001b[0;34m\u001b[0m\u001b[0m\n",
      "\u001b[0;31mClientError\u001b[0m: An error occurred (InvalidAccessKeyId) when calling the ListObjects operation: The AWS Access Key Id you provided does not exist in our records."
     ]
    }
   ],
   "source": [
    "for obj in s3client.list_objects(Bucket='mybucket')['Contents']:\n",
    "    try:  \n",
    "        filename = obj['Key'].rsplit('/', 1)[1]\n",
    "    except IndexError:\n",
    "        filename = obj['Key']\n",
    "\n",
    "    localfilename = os.path.join('/home/username/Downloads/', filename)  # The local directory must exist.\n",
    "    s3client.download_file('mybucket', obj['Key'], localfilename)"
   ]
  },
  {
   "cell_type": "code",
   "execution_count": null,
   "metadata": {},
   "outputs": [],
   "source": []
  }
 ],
 "metadata": {
  "kernelspec": {
   "display_name": "Environment (conda_python3)",
   "language": "python",
   "name": "conda_python3"
  },
  "language_info": {
   "codemirror_mode": {
    "name": "ipython",
    "version": 3
   },
   "file_extension": ".py",
   "mimetype": "text/x-python",
   "name": "python",
   "nbconvert_exporter": "python",
   "pygments_lexer": "ipython3",
   "version": "3.6.5"
  }
 },
 "nbformat": 4,
 "nbformat_minor": 2
}
